#VRML_SIM R2019a utf8
WorldInfo {
}
Viewpoint {
  orientation -0.7001396348506815 -0.570561985485325 -0.4292592601566081 1.6426491628800033
  position -0.17857098643001124 0.2800136111480608 -0.09659875845045918
}
TexturedBackground {
}
TexturedBackgroundLight {
}
Floor {
}
Robot {
  translation 0 0.05 0
  children [
    DEF BODY_GR Group {
      children [
        Transform {
          translation 0 0 0.06495
          rotation 0 1 0 0.523583333
          children [
            Shape {
              appearance DEF COLOR_BODY_ROBOT PBRAppearance {
                baseColor 0.7294117647058823 0.7411764705882353 0.7137254901960784
              }
              geometry DEF GEOMETRY_BODY_ROBOT Box {
                size 0.25 0.05 0.005
              }
            }
          ]
        }
        Transform {
          translation 0 0 -0.06495
          rotation 0 1 0 -0.523583
          children [
            Shape {
              appearance USE COLOR_BODY_ROBOT
              geometry USE GEOMETRY_BODY_ROBOT
            }
          ]
        }
        Transform {
          translation -0.111 0 0
          rotation 0 1 0 1.57
          children [
            Shape {
              appearance USE COLOR_BODY_ROBOT
              geometry USE GEOMETRY_BODY_ROBOT
            }
          ]
        }
        Transform {
          translation -0.11 0.025 -0.00069
          rotation 0 1 0 3.921592644
          children [
            Shape {
              appearance USE COLOR_BODY_ROBOT
              geometry IndexedFaceSet {
                coord Coordinate {
                  point [
                    0.09 0 -0.09
                    -0.155 0 -0.155
                    -0.09 0 0.09
                  ]
                }
                coordIndex [
                  0, 1, 2, -1
                ]
              }
            }
          ]
        }
      ]
    }
    DEF WHEELS_GR Group {
      children [
        Transform {
          translation -0.118 0 -0.14
          rotation 0 1 0 0.52
          children [
            HingeJoint {
              jointParameters HingeJointParameters {
                axis 0 0 1
              }
              endPoint Solid {
                rotation 0 0 1 0
                children [
                  DEF WHEEL_TR Transform {
                    rotation 1 0 0 1.57
                    children [
                      DEF WHEELS_SH Shape {
                        appearance DEF COLOR_WHEEL PBRAppearance {
                          baseColor 0 0 0
                          roughness 1
                          metalness 0
                        }
                        geometry DEF SIZE_WHEEL Cylinder {
                          height 0.03
                          radius 0.04
                        }
                      }
                    ]
                  }
                ]
                name "solid(2)"
                boundingObject USE WHEEL_TR
                physics Physics {
                }
              }
            }
            Transform {
              translation -7.963267107332634e-06 0.040000003170681656 0
              rotation 0 0 1 1.57
              children [
                HingeJoint {
                  jointParameters HingeJointParameters {
                    axis 0 1 0
                  }
                  endPoint Solid {
                    children [
                      Shape {
                        appearance PBRAppearance {
                          roughness 1
                          metalness 0
                        }
                        geometry Cylinder {
                          height 0.01
                          radius 0.005
                        }
                      }
                    ]
                  }
                }
              ]
            }
          ]
        }
      ]
    }
  ]
}
