#VRML_SIM R2019a utf8
WorldInfo {
}
Viewpoint {
  orientation 0.9329101289931773 -0.3185127848141416 -0.16801278859620702 5.253966730364249
  position 0.25069077363243975 0.7329577460495623 0.4151049134280512
  follow "robot"
}
TexturedBackground {
}
TexturedBackgroundLight {
}
Floor {
}
Robot {
  translation 0 0.05 0
  rotation 0 1 0 3.141592
  children [
    DEF BODY_GR Group {
      children [
        Transform {
          translation 0 0 0.06495
          rotation 0 1 0 0.523583333
          children [
            Shape {
              appearance DEF COLOR_BODY_ROBOT PBRAppearance {
                baseColor 0.7294117647058823 0.7411764705882353 0.7137254901960784
              }
              geometry DEF GEOMETRY_BODY_ROBOT Box {
                size 0.25 0.05 0.005
              }
            }
          ]
        }
        Transform {
          translation 0 0 -0.06495
          rotation 0 1 0 -0.523583
          children [
            Shape {
              appearance USE COLOR_BODY_ROBOT
              geometry USE GEOMETRY_BODY_ROBOT
            }
          ]
        }
        Transform {
          translation -0.111 0 0
          rotation 0 1 0 1.57
          children [
            Shape {
              appearance USE COLOR_BODY_ROBOT
              geometry USE GEOMETRY_BODY_ROBOT
            }
          ]
        }
        Transform {
          translation -0.11 0.025 -0.00069
          rotation 0 1 0 3.921592644
          children [
            Shape {
              appearance USE COLOR_BODY_ROBOT
              geometry IndexedFaceSet {
                coord Coordinate {
                  point [
                    0.09 0 -0.09
                    -0.155 0 -0.155
                    -0.09 0 0.09
                  ]
                }
                solid FALSE
                convex FALSE
                coordIndex [
                  0, 1, 2, -1
                ]
              }
            }
          ]
        }
      ]
    }
    DEF WHEELS_GR Group {
      children [
        DEF WHEEL_1 Transform {
          translation -0.115 0 -0.136
          rotation 0 1 0 0.52
          children [
            HingeJoint {
              jointParameters HingeJointParameters {
                axis 0 0 1
              }
              device [
                RotationalMotor {
                  name "motor1"
                  maxVelocity 30.36872
                  maxTorque 0.847386219999996
                }
                PositionSensor {
                  name "position_sensor1"
                  resolution 0.003848528
                }
              ]
              endPoint Solid {
                rotation 0 0 1 0
                children [
                  DEF WHEELS_TR1 Transform {
                    rotation 1 0 0 1.57
                    children [
                      DEF WHEELS_SH Shape {
                        appearance DEF COLOR_WHEEL PBRAppearance {
                          baseColor 0 0 0
                          roughness 1
                          metalness 0
                        }
                        geometry DEF SIZE_WHEEL Cylinder {
                          height 0.02
                          radius 0.04
                        }
                      }
                    ]
                  }
                  DEF SW1_1 HingeJoint {
                    jointParameters HingeJointParameters {
                      anchor 0 0.04 0
                    }
                    endPoint Solid {
                      translation 0 0.04 0
                      rotation 0 0 1 1.57
                      children [
                        DEF SMALL_WHEEL__TR1 Transform {
                          children [
                            DEF SMALL_WHEEL_SH Shape {
                              appearance PBRAppearance {
                                roughness 1
                                metalness 0
                              }
                              geometry Cylinder {
                                height 0.02
                                radius 0.005
                              }
                            }
                          ]
                        }
                      ]
                      boundingObject USE SMALL_WHEEL__TR1
                      physics Physics {
                      }
                    }
                  }
                  DEF SW1_2 HingeJoint {
                    jointParameters HingeJointParameters {
                      axis 1 -1 0
                      anchor 0.02828 0.02828 0
                    }
                    endPoint Solid {
                      translation 0.02828 0.02828 0
                      rotation 0 0 1 0.7852999999999999
                      children [
                        Transform {
                          children [
                            USE SMALL_WHEEL_SH
                          ]
                        }
                      ]
                      name "solid(1)"
                      boundingObject USE SMALL_WHEEL_SH
                      physics Physics {
                      }
                    }
                  }
                  DEF SW1_3 HingeJoint {
                    jointParameters HingeJointParameters {
                      axis 1 1 0
                      anchor -0.02828 0.02828 0
                    }
                    endPoint Solid {
                      translation -0.02828 0.02828 0
                      rotation 0 0 -1 0.7852999999999999
                      children [
                        Transform {
                          children [
                            USE SMALL_WHEEL_SH
                          ]
                        }
                      ]
                      name "solid(2)"
                      boundingObject USE SMALL_WHEEL_SH
                      physics Physics {
                      }
                    }
                  }
                  DEF SW1_4 HingeJoint {
                    jointParameters HingeJointParameters {
                      axis 0 1 0
                      anchor -0.04 0 0
                    }
                    endPoint Solid {
                      translation -0.04 0 0
                      children [
                        Transform {
                          children [
                            USE SMALL_WHEEL_SH
                          ]
                        }
                      ]
                      name "solid(3)"
                      boundingObject USE SMALL_WHEEL_SH
                      physics Physics {
                      }
                    }
                  }
                  DEF SW1_5 HingeJoint {
                    jointParameters HingeJointParameters {
                      axis 0 1 0
                      anchor 0.04 0 0
                    }
                    endPoint Solid {
                      translation 0.04 0 0
                      children [
                        Transform {
                          children [
                            USE SMALL_WHEEL_SH
                          ]
                        }
                      ]
                      name "solid(4)"
                      boundingObject USE SMALL_WHEEL_SH
                      physics Physics {
                      }
                    }
                  }
                  DEF SW1_6 HingeJoint {
                    jointParameters HingeJointParameters {
                      axis 1 -1 0
                      anchor -0.02828 -0.02828 0
                    }
                    endPoint Solid {
                      translation -0.02828 -0.02828 0
                      rotation 0 0 1 0.7852999999999999
                      children [
                        Transform {
                          children [
                            USE SMALL_WHEEL_SH
                          ]
                        }
                      ]
                      name "solid(5)"
                      boundingObject USE SMALL_WHEEL_SH
                      physics Physics {
                      }
                    }
                  }
                  DEF SW1_7 HingeJoint {
                    jointParameters HingeJointParameters {
                      axis 1 1 0
                      anchor 0.02828 -0.02828 0
                    }
                    endPoint Solid {
                      translation 0.02828 -0.02828 0
                      rotation 0 0 -1 0.7852999999999999
                      children [
                        Transform {
                          children [
                            USE SMALL_WHEEL_SH
                          ]
                        }
                      ]
                      name "solid(6)"
                      boundingObject USE SMALL_WHEEL_SH
                      physics Physics {
                      }
                    }
                  }
                  DEF SW1_8 HingeJoint {
                    jointParameters HingeJointParameters {
                      anchor 0 -0.04 0
                    }
                    endPoint Solid {
                      translation 0 -0.04 0
                      rotation 0 0 1 1.57
                      children [
                        Transform {
                          children [
                            USE SMALL_WHEEL_SH
                          ]
                        }
                      ]
                      name "solid(7)"
                      boundingObject USE SMALL_WHEEL_SH
                      physics Physics {
                      }
                    }
                  }
                ]
                name "solid(2)"
                boundingObject USE WHEELS_TR1
                physics Physics {
                }
              }
            }
          ]
        }
        DEF WHEEL_2 Transform {
          translation -0.115 0 0.136
          rotation 0 1 0 -0.52
          children [
            HingeJoint {
              jointParameters HingeJointParameters {
                axis 0 0 1
              }
              device [
                RotationalMotor {
                  name "motor2"
                  maxVelocity 30.36872
                  maxTorque 0.847386219999996
                }
                PositionSensor {
                  name "position_sensor2"
                  resolution 0.003848528
                }
              ]
              endPoint Solid {
                rotation 0 0 1 0
                children [
                  DEF WHEEL_TR2 Transform {
                    rotation 1 0 0 1.57
                    children [
                      USE WHEELS_SH
                    ]
                  }
                  DEF SW2_1 HingeJoint {
                    jointParameters HingeJointParameters {
                      anchor 0 0.04 0
                    }
                    endPoint Solid {
                      translation 0 0.04 0
                      rotation 0 0 1 1.57
                      children [
                        DEF SMALL_WHEEL_TR2 Transform {
                          children [
                            USE SMALL_WHEEL_SH
                          ]
                        }
                      ]
                      boundingObject USE SMALL_WHEEL_TR2
                      physics Physics {
                      }
                    }
                  }
                  DEF SW2_2 HingeJoint {
                    jointParameters HingeJointParameters {
                      axis 1 -1 0
                      anchor 0.02828 0.02828 0
                    }
                    endPoint Solid {
                      translation 0.02828 0.02828 0
                      rotation 0 0 1 0.7852999999999999
                      children [
                        Transform {
                          children [
                            USE SMALL_WHEEL_SH
                          ]
                        }
                      ]
                      name "solid(1)"
                      boundingObject USE SMALL_WHEEL_SH
                      physics Physics {
                      }
                    }
                  }
                  DEF SW2_3 HingeJoint {
                    jointParameters HingeJointParameters {
                      axis 1 1 0
                      anchor -0.02828 0.02828 0
                    }
                    endPoint Solid {
                      translation -0.02828 0.02828 0
                      rotation 0 0 -1 0.7852999999999999
                      children [
                        Transform {
                          children [
                            USE SMALL_WHEEL_SH
                          ]
                        }
                      ]
                      name "solid(2)"
                      boundingObject USE SMALL_WHEEL_SH
                      physics Physics {
                      }
                    }
                  }
                  DEF SW2_4 HingeJoint {
                    jointParameters HingeJointParameters {
                      axis 0 1 0
                      anchor -0.04 0 0
                    }
                    endPoint Solid {
                      translation -0.04 0 0
                      children [
                        Transform {
                          children [
                            USE SMALL_WHEEL_SH
                          ]
                        }
                      ]
                      name "solid(3)"
                      boundingObject USE SMALL_WHEEL_SH
                      physics Physics {
                      }
                    }
                  }
                  DEF SW2_5 HingeJoint {
                    jointParameters HingeJointParameters {
                      axis 0 1 0
                      anchor 0.04 0 0
                    }
                    endPoint Solid {
                      translation 0.04 0 0
                      rotation 0 1 0 1.57
                      children [
                        Transform {
                          children [
                            USE SMALL_WHEEL_SH
                          ]
                        }
                      ]
                      name "solid(4)"
                      boundingObject USE SMALL_WHEEL_SH
                      physics Physics {
                      }
                    }
                  }
                  DEF SW2_6 HingeJoint {
                    jointParameters HingeJointParameters {
                      axis 1 -1 0
                      anchor -0.02828 -0.02828 0
                    }
                    endPoint Solid {
                      translation -0.02828 -0.02828 0
                      rotation 0 0 1 0.7852999999999999
                      children [
                        Transform {
                          children [
                            USE SMALL_WHEEL_SH
                          ]
                        }
                      ]
                      name "solid(5)"
                      boundingObject USE SMALL_WHEEL_SH
                      physics Physics {
                      }
                    }
                  }
                  DEF SW2_7 HingeJoint {
                    jointParameters HingeJointParameters {
                      axis 1 1 0
                      anchor 0.02828 -0.02828 0
                    }
                    endPoint Solid {
                      translation 0.02828 -0.02828 0
                      rotation 0 0 -1 0.7852999999999999
                      children [
                        Transform {
                          children [
                            USE SMALL_WHEEL_SH
                          ]
                        }
                      ]
                      name "solid(6)"
                      boundingObject USE SMALL_WHEEL_SH
                      physics Physics {
                      }
                    }
                  }
                  DEF SW2_8 HingeJoint {
                    jointParameters HingeJointParameters {
                      anchor 0 -0.04 0
                    }
                    endPoint Solid {
                      translation 0 -0.04 0
                      rotation 0 0 1 1.57
                      children [
                        Transform {
                          children [
                            USE SMALL_WHEEL_SH
                          ]
                        }
                      ]
                      name "solid(7)"
                      boundingObject USE SMALL_WHEEL_SH
                      physics Physics {
                      }
                    }
                  }
                ]
                boundingObject USE WHEEL_TR2
                physics Physics {
                }
              }
            }
          ]
        }
        DEF WHEEL_3 Transform {
          translation 0.115 0 0
          rotation 0 1 0 1.57
          children [
            HingeJoint {
              jointParameters HingeJointParameters {
                axis 0 0 1
              }
              device [
                RotationalMotor {
                  name "motor3"
                  maxVelocity 30.36872
                  maxTorque 0.847386219999996
                }
                PositionSensor {
                  name "position_sensor3"
                  resolution 0.003848528
                }
              ]
              endPoint Solid {
                rotation 0 0 1 0
                children [
                  DEF WHEEL_TR3 Transform {
                    rotation 1 0 0 1.57
                    children [
                      USE WHEELS_SH
                    ]
                  }
                  DEF SW3_1 HingeJoint {
                    jointParameters HingeJointParameters {
                      anchor 0 0.04 0
                    }
                    endPoint Solid {
                      translation 0 0.04 0
                      rotation 0 0 1 1.57
                      children [
                        Transform {
                          children [
                            USE SMALL_WHEEL_SH
                          ]
                        }
                      ]
                      boundingObject USE SMALL_WHEEL_SH
                      physics Physics {
                      }
                    }
                  }
                  DEF SW3_2 HingeJoint {
                    jointParameters HingeJointParameters {
                      axis 1 -1 0
                      anchor 0.02828 0.02828 0
                    }
                    endPoint Solid {
                      translation 0.02828 0.02828 0
                      rotation 0 0 1 0.7852999999999999
                      children [
                        Transform {
                          children [
                            USE SMALL_WHEEL_SH
                          ]
                        }
                      ]
                      name "solid(1)"
                      boundingObject USE SMALL_WHEEL_SH
                      physics Physics {
                      }
                    }
                  }
                  DEF SW3_3 HingeJoint {
                    jointParameters HingeJointParameters {
                      axis 1 1 0
                      anchor -0.02828 0.02828 0
                    }
                    endPoint Solid {
                      translation -0.02828 0.02828 0
                      rotation 0 0 -1 0.7852999999999999
                      children [
                        Transform {
                          children [
                            USE SMALL_WHEEL_SH
                          ]
                        }
                      ]
                      name "solid(2)"
                      boundingObject USE SMALL_WHEEL_SH
                      physics Physics {
                      }
                    }
                  }
                  DEF SW3_4 HingeJoint {
                    jointParameters HingeJointParameters {
                      axis 0 1 0
                      anchor -0.04 0 0
                    }
                    endPoint Solid {
                      translation -0.04 0 0
                      children [
                        Transform {
                          children [
                            USE SMALL_WHEEL_SH
                          ]
                        }
                      ]
                      name "solid(3)"
                      boundingObject USE SMALL_WHEEL_SH
                      physics Physics {
                      }
                    }
                  }
                  DEF SW3_5 HingeJoint {
                    jointParameters HingeJointParameters {
                      axis 0 1 0
                      anchor 0.04 0 0
                    }
                    endPoint Solid {
                      translation 0.04 0 0
                      rotation 0 1 0 1.57
                      children [
                        Transform {
                          children [
                            USE SMALL_WHEEL_SH
                          ]
                        }
                      ]
                      name "solid(4)"
                      boundingObject USE SMALL_WHEEL_SH
                      physics Physics {
                      }
                    }
                  }
                  DEF SW3_6 HingeJoint {
                    jointParameters HingeJointParameters {
                      axis 1 -1 0
                      anchor -0.02828 -0.02828 0
                    }
                    endPoint Solid {
                      translation -0.02828 -0.02828 0
                      rotation 0 0 1 0.7852999999999999
                      children [
                        Transform {
                          children [
                            USE SMALL_WHEEL_SH
                          ]
                        }
                      ]
                      name "solid(5)"
                      boundingObject USE SMALL_WHEEL_SH
                      physics Physics {
                      }
                    }
                  }
                  DEF SW3_7 HingeJoint {
                    jointParameters HingeJointParameters {
                      axis 1 1 0
                      anchor 0.02828 -0.02828 0
                    }
                    endPoint Solid {
                      translation 0.02828 -0.02828 0
                      rotation 0 0 -1 0.7852999999999999
                      children [
                        Transform {
                          children [
                            USE SMALL_WHEEL_SH
                          ]
                        }
                      ]
                      name "solid(6)"
                      boundingObject USE SMALL_WHEEL_SH
                      physics Physics {
                      }
                    }
                  }
                  DEF SW3_8 HingeJoint {
                    jointParameters HingeJointParameters {
                      anchor 0 -0.04 0
                    }
                    endPoint Solid {
                      translation 0 -0.04 0
                      rotation 0 0 1 1.57
                      children [
                        Transform {
                          children [
                            USE SMALL_WHEEL_SH
                          ]
                        }
                      ]
                      name "solid(7)"
                      boundingObject USE SMALL_WHEEL_SH
                      physics Physics {
                      }
                    }
                  }
                ]
                name "solid(1)"
                boundingObject USE WHEEL_TR3
                physics Physics {
                }
              }
            }
          ]
        }
      ]
    }
    DistanceSensor {
      translation -0.115 0 -0.05
      rotation 0 1 0 3.14159
      children [
        Transform {
          rotation 0 1 0 -0.0872665
          children [
            DEF DISTANCE_SENSOR_SH Shape {
              appearance PBRAppearance {
                baseColor 0.9882352941176471 0.9137254901960784 0.30980392156862746
                roughness 1
                metalness 0
              }
              geometry Box {
                size 0.01 0.01 0.01
              }
            }
          ]
        }
      ]
      lookupTable [
        0 0 0
        0.2 65536 0
      ]
      resolution 1
    }
    DistanceSensor {
      translation -0.115 0 0.05
      rotation 0 1 0 3.14159
      children [
        Transform {
          rotation 0 1 0 0.0872665
          children [
            USE DISTANCE_SENSOR_SH
          ]
        }
      ]
      name "distance sensor(1)"
      lookupTable [
        0 0 0
        0.2 65536 0
      ]
    }
  ]
  boundingObject USE BODY_GR
  physics Physics {
    density 2000
    centerOfMass [
      0 0 0
    ]
  }
  controller "u3_exam_Espinoza_Angelo"
}
